Workbook

Sheet kinopoisk-top250
A1: rating | B1: movie | C1: year | D1: country | E1: rating_ball | F1: overview | G1: director | H1: screenwriter | I1: actors | J1: url_logo
A2: 0 | B2: Побег из Шоушенка | C2: 1994 | D2: США | E2: 9.111 | F2: Бухгалтер Энди Дюфрейн обвинён в убийстве собственной жены и её любовника. Оказавшись в тюрьме под названием Шоушенк; он сталкивается с жестокостью и беззаконием; царящими по обе стороны решётки. Каждый; кто попадает в эти стены; становится их рабом до конца жизни. Но Энди; обладающий живым умом и доброй душой; находит подход как к заключённым; так и к охранникам; добиваясь их особого к себе расположения. | G2: Фрэнк Дарабонт | H2: Фрэнк Дарабонт; Стивен Кинг | I2: Тим Роббинс; Морган Фриман; Боб Гантон; Уильям Сэдлер; Клэнси Браун | J2: 'https://st.kp.yandex.net/images/film_iphone/iphone360_326.jpg'
A3: 1 | B3: Зеленая миля | C3: 1999 | D3: США | E3: 9.062 | F3: Пол Эджкомб — начальник блока смертников в тюрьме «Холодная гора»; каждый из узников которого однажды проходит «зеленую милю» по пути к месту казни. Пол повидал много заключённых и надзирателей за время работы. Однако гигант Джон Коффи; обвинённый в страшном преступлении; стал одним из самых необычных обитателей блока. | G3: Фрэнк Дарабонт | H3: Фрэнк Дарабонт; Стивен Кинг | I3: Том Хэнкс; Дэвид Морс; Бонни Хант; Майкл Кларк Дункан; Джеймс Кромуэлл | J3: 'https://st.kp.yandex.net/images/film_iphone/iphone360_435.jpg'
A4: 2 | B4: Форрест Гамп | C4: 1994 | D4: США | E4: 8.913 | F4: От лица главного героя Форреста Гампа; слабоумного безобидного человека с благородным и открытым сердцем; рассказывается история его необыкновенной жизни.Фантастическим образом превращается он в известного футболиста; героя войны; преуспевающего бизнесмена. Он становится миллиардером; но остается таким же бесхитростным; глупым и добрым. Форреста ждет постоянный успех во всем; а он любит девочку; с которой дружил в детстве; но взаимность приходит слишком поздно. | G4: Роберт Земекис | H4: Эрик Рот; Уинстон Грум | I4: Том Хэнкс; Робин Райт; Салли Филд; Гэри Синиз; Майкелти Уильямсон | J4: 'https://st.kp.yandex.net/images/film_iphone/iphone360_448.jpg'
A5: 3 | B5: Список Шиндлера | C5: 1993 | D5: США | E5: 8.817 | F5: Фильм рассказывает реальную историю загадочного Оскара Шиндлера; члена нацистской партии; преуспевающего фабриканта; спасшего во время Второй мировой войны почти 1200 евреев. | G5: Стивен Спилберг | H5: Стивен Зеллиан; Томас Кенилли | I5: Лиам Нисон; Бен Кингсли; Рэйф Файнс; Кэролайн Гудолл; Эмбет Дэвидц | J5: 'https://st.kp.yandex.net/images/film_iphone/iphone360_329.jpg'
A6: 4 | B6: 1+1 | C6: 2011 | D6: Франция | E6: 8.807 | F6: Пострадав в результате несчастного случая; богатый аристократ Филипп нанимает в помощники человека; который менее всего подходит для этой работы; — молодого жителя предместья Дрисса; только что освободившегося из тюрьмы. Несмотря на то; что Филипп прикован к инвалидному креслу; Дриссу удается привнести в размеренную жизнь аристократа дух приключений. | G6: Оливье Накаш; Эрик Толедано | H6: Оливье Накаш; Филипп Поццо ди Борго; Эрик Толедано | I6: Франсуа Клюзе; Омар Си; Анн Ле Ни; Одри Флеро; Жозефин де Мо | J6: 'https://st.kp.yandex.net/images/film_iphone/iphone360_535341.jpg'
A7: 5 | B7: Начало | C7: 2010 | D7: США | E7: 8.662 | F7: Кобб — талантливый вор; лучший из лучших в опасном искусстве извлечения: он крадет ценные секреты из глубин подсознания во время сна; когда человеческий разум наиболее уязвим. Редкие способности Кобба сделали его ценным игроком в привычном к предательству мире промышленного шпионажа; но они же превратили его в извечного беглеца и лишили всего; что он когда-либо любил. И вот у Кобба появляется шанс исправить ошибки. Его последнее дело может вернуть все назад; но для этого ему нужно совершить невозможное — инициацию. Вместо идеальной кражи Кобб и его команда спецов должны будут провернуть обратное. Теперь их задача — не украсть идею; а внедрить ее. Если у них получится; это и станет идеальным преступлением. Но никакое планирование или мастерство не могут подготовить команду к встрече с опасным противником; который; кажется; предугадывает каждый их ход. Врагом; увидеть которого мог бы лишь Кобб. | G7: Кристофер Нолан | H7: Кристофер Нолан | I7: Леонардо ДиКаприо; Джозеф Гордон-Левитт; Эллен Пейдж; Том Харди; Кэн Ватанабэ | J7: 'https://st.kp.yandex.net/images/film_iphone/iphone360_447301.jpg'
A8: 6 | B8: Леон | C8: 1994 | D8: Франция | E8: 8.681 | F8: Профессиональный убийца Леон; не знающий пощады и жалости; знакомится со своей очаровательной соседкой Матильдой; семью которой расстреливают полицейские; замешанные в торговле наркотиками. Благодаря этому знакомству он впервые испытывает чувство любви; но… | G8: Люк Бессон | H8: Люк Бессон | I8: Жан Рено; Гари Олдман; Натали Портман; Дэнни Айелло; Питер Эппел | J8: 'https://st.kp.yandex.net/images/film_iphone/iphone360_389.jpg'
A9: 7 | B9: Король Лев | C9: 1994 | D9: США | E9: 8.772 | F9: У величественного Короля-Льва Муфасы рождается наследник по имени Симба. Уже в детстве любознательный малыш становится жертвой интриг своего завистливого дяди Шрама; мечтающего о власти.Симба познаёт горе утраты; предательство и изгнание; но в конце концов обретает верных друзей и находит любимую. Закалённый испытаниями; он в нелёгкой борьбе отвоёвывает своё законное место в «Круге жизни»; осознав; что значит быть настоящим Королём. | G9: Роджер Аллерс; Роб Минкофф | H9: Ирен Меччи; Джонатан Робертс; Линда Вулвертон; ... | I9: Мэттью Бродерик; Джереми Айронс; Нэйтан Лейн; Эрни Сабелла; Джеймс Эрл Джонс | J9: 'https://st.kp.yandex.net/images/film_iphone/iphone360_2360.jpg'
A10: 8 | B10: Бойцовский клуб | C10: 1999 | D10: США | E10: 8.645 | F10: Сотрудник страховой компании страдает хронической бессонницей и отчаянно пытается вырваться из мучительно скучной жизни. Однажды в очередной командировке он встречает некоего Тайлера Дёрдена — харизматического торговца мылом с извращенной философией. Тайлер уверен; что самосовершенствование — удел слабых; а единственное; ради чего стоит жить — саморазрушение.Проходит немного времени; и вот уже новые друзья лупят друг друга почем зря на стоянке перед баром; и очищающий мордобой доставляет им высшее блаженство. Приобщая других мужчин к простым радостям физической жестокости; они основывают тайный Бойцовский клуб; который начинает пользоваться невероятной популярностью. | G10: Дэвид Финчер | H10: Джим Улс; Чак Паланик | I10: Эдвард Нортон; Брэд Питт; Хелена Бонем Картер; Мит Лоаф; Зэк Гренье | J10: 'https://st.kp.yandex.net/images/film_iphone/iphone360_361.jpg'
A11: 9 | B11: Иван Васильевич меняет профессию | C11: 1973 | D11: СССР | E11: 8.782 | F11: Инженер-изобретатель Тимофеев сконструировал машину времени; которая соединила его квартиру с далеким шестнадцатым веком — точнее; с палатами государя Ивана Грозного. Туда-то и попадают тезка царя пенсионер-общественник Иван Васильевич Бунша и квартирный вор Жорж Милославский.На их место в двадцатом веке «переселяется» великий государь. Поломка машины приводит ко множеству неожиданных и забавных событий… | G11: Леонид Гайдай | H11: Владлен Бахнов; Леонид Гайдай; Михаил Булгаков | I11: Александр Демьяненко; Юрий Яковлев; Леонид Куравлёв; Наталья Крачковская; Савелий Крамаров | J11: 'https://st.kp.yandex.net/images/film_iphone/iphone360_42664.jpg'
A12: 10 | B12: Жизнь прекрасна | C12: 1997 | D12: Италия | E12: 8.624 | F12: Во время II Мировой войны в Италии в концлагерь были отправлены евреи; отец и его маленький сын. Жена; итальянка; добровольно последовала вслед за ними. В лагере отец сказал сыну; что все происходящее вокруг является очень большой игрой за приз в настоящий танк; который достанется тому мальчику; который сможет не попасться на глаза надзирателям. | G12: Роберто Бениньи | H12: Винченцо Черами; Роберто Бениньи | I12: Роберто Бениньи; Николетта Браски; Джорджио Кантарини; Джустино Дурано; Серджио Бини Бустрик | J12: 'https://st.kp.yandex.net/images/film_iphone/iphone360_381.jpg'
A13: 11 | B13: Достучаться до небес | C13: 1997 | D13: Германия | E13: 8.629 | F13: Судьба сводит героев картины в больнице; где врачи выносят им смертный приговор. Счет времени их жизней идет на часы. Дальнейшие события в фильме разворачиваются в стремительном темпе. Украв машину с миллионом немецких марок в багажнике; они сбегают из больницы.Их преследуют наемные убийцы; они становятся грабителями поневоле; за ними гонится полиция; они попадают в бордель. Но тем не менее продолжают мчаться вперед; навстречу своей судьбе. | G13: Томас Ян | H13: Томас Ян; Тиль Швайгер | I13: Тиль Швайгер; Ян Йозеф Лиферс; Тьерри Ван Вервеке; Мориц Бляйбтрой; Хуб Стапель | J13: 'https://st.kp.yandex.net/images/film_iphone/iphone360_32898.jpg'
... A251: 249 | B251: Холодное лето пятьдесят третьего... | C251: 1987 | D251: СССР | E251: 8.05 | F251: Двое бывших политзаключённых; недавно вышедших из лагеря; вступают в схватку с бандой амнистированных уголовников. Победу приходится оплатить дорогой ценой.Почти детективная история неравного поединка заканчивается и оптимистически; и трагически. Время действия — 1953 год; страна на пороге больших перемен… | G251: Александр Прошкин | H251: Эдгар Дубровский | I251: Валерий Приёмыхов; Анатолий Папанов; Виктор Степанов; Нина Усатова; Зоя Буряк | J251: 'https://st.kp.yandex.net/images/film_iphone/iphone360_7660.jpg'

Sheet Long
A1: ='kinopoisk-top250'!B1 -> movie | B1: ='kinopoisk-top250'!C1 -> year | C1: length
A2: ='kinopoisk-top250'!B54 -> Приключения Шерлока Холмса и доктора Ватсона: Собака Баскервилей | B2: ='kinopoisk-top250'!C54 -> 1981 | C2: =LEN(A2) -> 65
A3: ='kinopoisk-top250'!B120 -> Приключения Шерлока Холмса и доктора Ватсона: Охота на тигра | B3: ='kinopoisk-top250'!C120 -> 1980 | C3: =LEN(A3) -> 61
A4: ='kinopoisk-top250'!B229 -> Звёздные войны: Эпизод 5 – Империя наносит ответный удар | B4: ='kinopoisk-top250'!C229 -> 1980 | C4: =LEN(A4) -> 57
A5: ='kinopoisk-top250'!B37 -> Пираты Карибского моря: Проклятие Черной жемчужины | B5: ='kinopoisk-top250'!C37 -> 2003 | C5: =LEN(A5) -> 51
A6: ='kinopoisk-top250'!B49 -> Кавказская пленница; или Новые приключения Шурика | B6: ='kinopoisk-top250'!C49 -> 1966 | C6: =LEN(A6) -> 50
A7: ='kinopoisk-top250'!B102 -> Шерлок Холмс и доктор Ватсон: Смертельная схватка | B7: ='kinopoisk-top250'!C102 -> 1980 | C7: =LEN(A7) -> 50
A8: ='kinopoisk-top250'!B122 -> Добро пожаловать; или Посторонним вход воспрещен | B8: ='kinopoisk-top250'!C122 -> 1964 | C8: =LEN(A8) -> 49
A9: ='kinopoisk-top250'!B111 -> Шерлок Холмс и доктор Ватсон: Кровавая надпись | B9: ='kinopoisk-top250'!C111 -> 1979 | C9: =LEN(A9) -> 47
A10: ='kinopoisk-top250'!B189 -> Звёздные войны: Эпизод 6 – Возвращение Джедая | B10: ='kinopoisk-top250'!C189 -> 1983 | C10: =LEN(A10) -> 46
A11: ='kinopoisk-top250'!B130 -> Шерлок Холмс и доктор Ватсон: Король шантажа | B11: ='kinopoisk-top250'!C130 -> 1980 | C11: =LEN(A11) -> 45
A12: ='kinopoisk-top250'!B139 -> Шерлок Холмс и доктор Ватсон: Сокровища Агры | B12: ='kinopoisk-top250'!C139 -> 1983 | C12: =LEN(A12) -> 45
A13: ='kinopoisk-top250'!B182 -> Индиана Джонс и последний крестовый поход | B13: ='kinopoisk-top250'!C182 -> 1989 | C13: =LEN(A13) -> 42
A14: ='kinopoisk-top250'!B16 -> Операция «Ы» и другие приключения Шурика | B14: ='kinopoisk-top250'!C16 -> 1965 | C14: =LEN(A14) -> 41
A15: ='kinopoisk-top250'!B67 -> Шерлок Холмс и доктор Ватсон: Знакомство | B15: ='kinopoisk-top250'!C67 -> 1979 | C15: =LEN(A15) -> 41
A16: ='kinopoisk-top250'!B166 -> Три билборда на границе Эббинга; Миссури | B16: ='kinopoisk-top250'!C166 -> 2017 | C16: =LEN(A16) -> 41
A17: ='kinopoisk-top250'!B174 -> Звёздные войны: Эпизод 3 – Месть Ситхов | B17: ='kinopoisk-top250'!C174 -> 2005 | C17: =LEN(A17) -> 40
A18: ='kinopoisk-top250'!B145 -> Пираты Карибского моря: Сундук мертвеца | B18: ='kinopoisk-top250'!C145 -> 2006 | C18: =LEN(A18) -> 40
A19: ='kinopoisk-top250'!B248 -> Пираты Карибского моря: На краю Света | B19: ='kinopoisk-top250'!C248 -> 2007 | C19: =LEN(A19) -> 38
A20: ='kinopoisk-top250'!B205 -> Загадочная история Бенджамина Баттона | B20: ='kinopoisk-top250'!C205 -> 2008 | C20: =LEN(A20) -> 38
A21: ='kinopoisk-top250'!B214 -> Гарри Поттер и Дары Смерти: Часть II | B21: ='kinopoisk-top250'!C214 -> 2011 | C21: =LEN(A21) -> 37
A22: ='kinopoisk-top250'!B251 -> Холодное лето пятьдесят третьего... | B22: ='kinopoisk-top250'!C251 -> 1987 | C22: =LEN(A22) -> 36
A23: ='kinopoisk-top250'!B20 -> Властелин колец: Возвращение Короля | B23: ='kinopoisk-top250'!C20 -> 2003 | C23: =LEN(A23) -> 36
A24: ='kinopoisk-top250'!B200 -> Ирония судьбы; или С легким паром! | B24: ='kinopoisk-top250'!C200 -> 1975 | C24: =LEN(A24) -> 35
A25: ='kinopoisk-top250'!B94 -> Темный рыцарь: Возрождение легенды | B25: ='kinopoisk-top250'!C94 -> 2012 | C25: =LEN(A25) -> 35
A26: ='kinopoisk-top250'!B210 -> Гарри Поттер и философский камень | B26: ='kinopoisk-top250'!C210 -> 2001 | C26: =LEN(A26) -> 34
A27: ='kinopoisk-top250'!B11 -> Иван Васильевич меняет профессию | B27: ='kinopoisk-top250'!C11 -> 1973 | C27: =LEN(A27) -> 33
A28: ='kinopoisk-top250'!B29 -> Властелин колец: Братство кольца | B28: ='kinopoisk-top250'!C29 -> 2001 | C28: =LEN(A28) -> 33
A29: ='kinopoisk-top250'!B159 -> В случае убийства набирайте «М» | B29: ='kinopoisk-top250'!C159 -> 1954 | C29: =LEN(A29) -> 32
A30: ='kinopoisk-top250'!B244 -> История игрушек: Большой побег | B30: ='kinopoisk-top250'!C244 -> 2010 | C30: =LEN(A30) -> 31
A31: ='kinopoisk-top250'!B34 -> Властелин колец: Две крепости | B31: ='kinopoisk-top250'!C34 -> 2002 | C31: =LEN(A31) -> 30
A32: ='kinopoisk-top250'!B197 -> Гарри Поттер и узник Азкабана | B32: ='kinopoisk-top250'!C197 -> 2004 | C32: =LEN(A32) -> 30
A33: ='kinopoisk-top250'!B231 -> Рапунцель: Запутанная история | B33: ='kinopoisk-top250'!C231 -> 2010 | C33: =LEN(A33) -> 30
A34: ='kinopoisk-top250'!B108 -> Хоббит: Нежданное путешествие | B34: ='kinopoisk-top250'!C108 -> 2012 | C34: =LEN(A34) -> 30
A35: ='kinopoisk-top250'!B147 -> На несколько долларов больше | B35: ='kinopoisk-top250'!C147 -> 1965 | C35: =LEN(A35) -> 29
A36: ='kinopoisk-top250'!B40 -> Пролетая над гнездом кукушки | B36: ='kinopoisk-top250'!C40 -> 1975 | C36: =LEN(A36) -> 29
A37: ='kinopoisk-top250'!B165 -> Вечное сияние чистого разума | B37: ='kinopoisk-top250'!C165 -> 2004 | C37: =LEN(A37) -> 29
A38: ='kinopoisk-top250'!B192 -> Новый кинотеатр «Парадизо» | B38: ='kinopoisk-top250'!C192 -> 1988 | C38: =LEN(A38) -> 27
A39: ='kinopoisk-top250'!B112 -> Мальчик в полосатой пижаме | B39: ='kinopoisk-top250'!C112 -> 2008 | C39: =LEN(A39) -> 27
A40: ='kinopoisk-top250'!B30 -> В бой идут одни «старики» | B40: ='kinopoisk-top250'!C30 -> 1973 | C40: =LEN(A40) -> 26
...
